Workbook

Sheet DD Full Checklist
D2: PROJECT TEAM KICKOFF CHECKLIST | F2: KEY DATES | H2: DAYS REMAINING | I2: Days Passed
D3: RAP UP Portfolio, Roxbury, MA | F3: LOI executed | G3: 46013 | H3: =MAX(G3-TODAY(),0) -> 0 | I3: =+MAX(TODAY()-G3,0) -> 204
F4: Seller deadline to sent DD request | G4: 46030 | H4: =MAX(G4-TODAY(),0) -> 0 | I4: =+MAX(TODAY()-G4,0) -> 187
F5: Initial Deposit ($50K) | G5: 46101 | H5: =MAX(G5-TODAY(),0) -> 0 | I5: =+MAX(TODAY()-G5,0) -> 116
F6: Rollover TS | G6: =+G5+30 -> 46131 | H6: =MAX(G6-TODAY(),0) -> 0 | I6: =+MAX(TODAY()-G6,0) -> 86
F7: End of DD / 2nd Deposit ($150K) | G7: =+G5+60 -> 46161 | H7: =MAX(G7-TODAY(),0) -> 0 | I7: =+MAX(TODAY()-G7,0) -> 56
F8: Buyer to send JV OA | G8: =+G7+30 -> 46191 | H8: =MAX(G8-TODAY(),0) -> 0 | I8: =+MAX(TODAY()-G8,0) -> 26
F9: Seller to confirm Rollover terms | G9: =+G5+105 -> 46206 | H9: =MAX(G9-TODAY(),0) -> 0 | I9: =+MAX(TODAY()-G9,0) -> 11
F10: Projected HUD Approval | G10: 46253 | H10: =MAX(G10-TODAY(),0) -> 36 | I10: =+MAX(TODAY()-G10,0) -> 0
F11: Projected Closing | G11: =+G10+30 -> 46283 | H11: =MAX(G11-TODAY(),0) -> 66 | I11: =+MAX(TODAY()-G11,0) -> 0
F12: Outside Closing Date | G12: =+G5+30*6+30 -> 46311 | H12: =MAX(G12-TODAY(),0) -> 94 | I12: =+MAX(TODAY()-G12,0) -> 0 | N12: =+TODAY() -> 46217
C14: DIV Folder | D14: Item # | E14: Action Item | F14: Status | G14: Responsible Party | H14: External Party | I14: Outside Date | J14: CC Comment | K14: Partner Comment | N14: Days Remaining
D15: Equity Financing
D16: =+MAX($D$14:D15)+1 -> 1 | E16: Create Investor log/tracker | F16: Closed | G16: PK | I16: Ongoing | M16: INTERNAL | N16: =IF(OR($F16="Closed",ISBLANK(I16)),"-",IFERROR(MAX(I16-$N$12,0),"-")) -> -
D17: =+MAX($D$14:D16)+1 -> 2 | E17: Draft initial investor email | F17: Closed | G17: PK | I17: 46027 | M17: INTERNAL | N17: =IF(OR($F17="Closed",ISBLANK(I17)),"-",IFERROR(MAX(I17-$N$12,0),"-")) -> -
D18: =+MAX($D$14:D17)+1 -> 3 | E18: Set up Smallchange account | F18: Closed | G18: PK | I18: 46082 | J18: $10k set up fee + 7% success fee | M18: INTERNAL | N18: =IF(OR($F18="Closed",ISBLANK(I18)),"-",IFERROR(MAX(I18-$N$12,0),"-")) -> -
D19: =+MAX($D$14:D18)+1 -> 4 | E19: Finalize and confirm special GP Investor roster | F19: Open | G19: PK | I19: =+G11-60 -> 46223 | J19: Discuss funding of 2% UPB. Send out this week. Drop individual signature blocks for individuals | M19: INTERNAL | N19: =IF(OR($F19="Closed",ISBLANK(I19)),"-",IFERROR(MAX(I19-$N$12,0),"-")) -> 6
D20: =+MAX($D$14:D19)+1 -> 5 | E20: Confirm special co-GP AMF approach | F20: Open | G20: BA | J20: CC internal to discuss before sending materials
D21: =+MAX($D$14:D20)+1 -> 6 | E21: Finalize Caste investment OM | F21: Open | G21: BA | I21: 46082 | J21: Update OM with latest financials/deal | M21: INTERNAL | N21: =IF(OR($F21="Closed",ISBLANK(I21)),"-",IFERROR(MAX(I21-$N$12,0),"-")) -> 0
D22: Debt Financing | N22: =IF(OR($F22="Closed",ISBLANK(I22)),"-",IFERROR(MAX(I22-$N$12,0),"-")) -> -
D23: =+MAX($D$14:D22)+1 -> 7 | E23: Draft list of prospective lenders to send materials | F23: Closed | G23: AS | I23: TBC | N23: =IF(OR($F23="Closed",ISBLANK(I23)),"-",IFERROR(MAX(I23-$N$12,0),"-")) -> -
D24: =+MAX($D$14:D23)+1 -> 8 | E24: Create Lender OM - updated Model, S+U, OM, Rent Roll | F24: Closed | G24: AS | I24: TBC | J24: Update as more recent DD materials come in | N24: =IF(OR($F24="Closed",ISBLANK(I24)),"-",IFERROR(MAX(I24-$N$12,0),"-")) -> -
D25: =+MAX($D$14:D24)+1 -> 9 | E25: Create Lender tracker | F25: Closed | G25: AS | I25: TBC | J25: See Teams | N25: =IF(OR($F25="Closed",ISBLANK(I25)),"-",IFERROR(MAX(I25-$N$12,0),"-")) -> -
D26: =+MAX($D$14:D25)+1 -> 10 | E26: Provide feedback on loan options and impacts to business plan | F26: Closed | H26: Jacques | I26: TBC | J26: Going back to NM and WD for best and final | N26: =IF(OR($F26="Closed",ISBLANK(I26)),"-",IFERROR(MAX(I26-$N$12,0),"-")) -> -
D27: =+MAX($D$14:D26)+1 -> 11 | E27: W& D UW DD CHECKLIST | F27: Open | I27: TBC | J27: Received. Send relevant items to UHM. Schedule call to discuss updated financials & A/R. | N27: =IF(OR($F27="Closed",ISBLANK(I27)),"-",IFERROR(MAX(I27-$N$12,0),"-")) -> -
D28: =+MAX($D$14:D27)+1 -> 12 | E28: W&D: PCA/ESA/PLAN & COST CHECKLIST | F28: Open | I28: TBC | J28: Received. CC sent the materials needed. UHM must complete pipe work bbefore we close | N28: =IF(OR($F28="Closed",ISBLANK(I28)),"-",IFERROR(MAX(I28-$N$12,0),"-")) -> -
D29: Legal - Transaction | N29: =IF(OR($F29="Closed",ISBLANK(I29)),"-",IFERROR(MAX(I29-$N$12,0),"-")) -> -
D30: =+MAX($D$14:D29)+1 -> 13 | E30: Draft, review and execute PSA | F30: Closed | G30: PK | H30: Nixon | I30: 46101 | J30: Executed 3/20 | N30: =IF(OR($F30="Closed",ISBLANK(I30)),"-",IFERROR(MAX(I30-$N$12,0),"-")) -> -
D31: =+MAX($D$14:D30)+1 -> 14 | E31: Run down cost estimates for all Goodwin legal | F31: Closed | G31: PK | H31: Goodwin | I31: 46063 | J31: $2,900. To confirm on timing. Bank account is opened | N31: =IF(OR($F31="Closed",ISBLANK(I31)),"-",IFERROR(MAX(I31-$N$12,0),"-")) -> -
D32: =+MAX($D$14:D31)+1 -> 15 | E32: Confirm if Menkiti drafting GP JVA | F32: Closed | G32: PK | H32: MG | I32: 46068 | J32: MG drafting | N32: =IF(OR($F32="Closed",ISBLANK(I32)),"-",IFERROR(MAX(I32-$N$12,0),"-")) -> -
D33: =+MAX($D$14:D32)+1 -> 16 | E33: Confirm if Menkiti drafting LPA (Co-GPs and OCF) | F33: Closed | G33: PK | H33: MG | I33: 46014 | J33: MG drafting | N33: =IF(OR($F33="Closed",ISBLANK(I33)),"-",IFERROR(MAX(I33-$N$12,0),"-")) -> -
D34: =+MAX($D$14:D33)+1 -> 17 | E34: Set up JV OA: (CC, MG, OCF LP) | F34: Open | G34: PK | H34: MG, Goodwin | J34: Discussing with Seller | N34: =IF(OR($F34="Closed",ISBLANK(I34)),"-",IFERROR(MAX(I34-$N$12,0),"-")) -> - | P34: HUD needs draft. CC decide on date needed by
D35: =+MAX($D$14:D34)+1 -> 18 | E35: Set GP OA: (CC, MG) | F35: Open | G35: PK | H35: MG | J35: MG drafting. Awaiting first draft | N35: =IF(OR($F35="Closed",ISBLANK(I35)),"-",IFERROR(MAX(I35-$N$12,0),"-")) -> - | P35: HUD needs draft. CC decide on date needed by
D36: =+MAX($D$14:D35)+1 -> 19 | E36: Set up Caste OA: (CC Partners, Special Co-GP) | F36: Closed | G36: PK | H36: Goodwin | I36: 46143 | J36: Document has been finalized | M36: INTERNAL | N36: =IF(OR($F36="Closed",ISBLANK(I36)),"-",IFERROR(MAX(I36-$N$12,0),"-")) -> -
D37: =+MAX($D$14:D36)+1 -> 20 | E37: Set up RAP UP Partners LLC deal (CC Partners) | F37: Closed | G37: PK | I37: 46148 | J37: Register entity in DA. Bank needs OA, EIN, articles of incorp. DS to circulate final doc. PK to set up entity | M37: INTERNAL | N37: =IF(OR($F37="Closed",ISBLANK(I37)),"-",IFERROR(MAX(I37-$N$12,0),"-")) -> -
D38: =+MAX($D$14:D37)+1 -> 21 | E38: Escrow $50K Deposit at PSA execution | F38: Closed | G38: PK | H38: MG | I38: =WORKDAY($G$5,5) -> 46108 | N38: =IF(OR($F38="Closed",ISBLANK(I38)),"-",IFERROR(MAX(I38-$N$12,0),"-")) -> -
D39: =+MAX($D$14:D38)+1 -> 22 | E39: Escrow $150K Deposit at DD exit | F39: Closed | G39: PK | H39: MG | I39: =WORKDAY($G$7,5) -> 46168 | N39: =IF(OR($F39="Closed",ISBLANK(I39)),"-",IFERROR(MAX(I39-$N$12,0),"-")) -> -
D40: =+MAX($D$14:D39)+1 -> 23 | E40: Draft / Review PMA | F40: Closed | G40: DS | H40: Nixon/MG | J40: Finalizing remaining language. | N40: =IF(OR($F40="Closed",ISBLANK(I40)),"-",IFERROR(MAX(I40-$N$12,0),"-")) -> -
D41: =+MAX($D$14:D40)+1 -> 24 | E41: Release Murphy Consulting on HUD 2530 Clearance | F41: Open | H41: MG / Murphy | J41: In waiting mode. | N41: =IF(OR($F41="Closed",ISBLANK(I41)),"-",IFERROR(MAX(I41-$N$12,0),"-")) -> -
D42: =+MAX($D$14:D41)+1 -> 25 | E42: Confirm EOHLC's waiver | F42: Open | G42: PK | I42: 46178 | J42: Received 40T exemption letter on 7/13
...

Sheet Internal - DD Request List
D2: DUE DILIGENCE REQUEST LIST | F2: UPDATED AS OF:
D3: RAP UP Portfolio | F3: 46035
I4: =+TODAY() -> 46217
C5: DIV Folder | D5: Item # | E5: Document | F5: Status | G5: Department | H5: Responsible Party | I5: DIV Comment | J5: Partner Comment | K5: Notes
D6: LEASING & MARKETING
D7: =+MAX($D$5:D5)+1 -> 1 | E7: Review Residential Leases & House Rules | F7: Open | G7: Leasing / Marketing | K7: Rec'd House Rules, Form Lease, need all leases, LEASES ON SITE NEED TO REVIEW
D8: =+MAX($D$5:D7)+1 -> 2 | E8: Review License Agreements (if applicable) | F8: Closed | G8: Leasing / Marketing | K8: Seller: N/A
D9: =+MAX($D$5:D8)+1 -> 3 | E9: Review Indemnities (if applicable) | F9: Closed | G9: Leasing / Marketing | K9: Seller: N/A
D10: PHYSICAL / PROPERTY
E11: Title and Zoning review | G11: Development
D12: =+MAX($D$5:D11)+1 -> 4 | E12: ALTA Survey | F12: Closed | G12: Development | K12: Seller: N/A
D13: =+MAX($D$5:D12)+1 -> 5 | E13: Title Commitment | F13: Open | G13: Development | K13: Owners & Lender Policy
D14: =+MAX($D$5:D13)+1 -> 6 | E14: Deleted | F14: Deleted | G14: Deleted
D15: =+MAX($D$5:D14)+1 -> 7 | E15: All City/State permits | F15: Closed | G15: Development | K15: Seller: N/A
D16: =+MAX($D$5:D15)+1 -> 8 | E16: Easement Documents (if applicable) | F16: Closed | G16: Development | K16: Seller: N/A
D17: =+MAX($D$5:D16)+1 -> 9 | E17: Confirm FEMA Flood Vulnerable Status | F17: Closed | G17: Development | K17: Seller: N/A
D18: =+MAX($D$5:D17)+1 -> 10 | E18: Permits Required for Property Operation (e.g. flammable fuel storage) | F18: Closed | G18: Development | K18: Seller: N/A
E19: Environmental Information review
D20: =+MAX($D$5:D19)+1 -> 11 | E20: Phase 1 ESA | F20: Closed | G20: Development | K20: Seller: N/A
D21: =+MAX($D$5:D20)+1 -> 12 | E21: Hazardous Materials report | F21: Closed | G21: Development | K21: Seller: N/A
D22: =+MAX($D$5:D21)+1 -> 13 | E22: Geotechnical soils report | F22: Closed | G22: Development | K22: Seller: N/A
D23: =+MAX($D$5:D22)+1 -> 14 | E23: Lead abatement/compliance report | F23: Received | G23: Development | K23: Letter of Full Deleading Compliance, 11/17/1998
D24: =+MAX($D$5:D23)+1 -> 15 | E24: Mold reports/remediation | F24: Closed | G24: Development | K24: Seller: N/A
D25: =+MAX($D$5:D24)+1 -> 16 | E25: Indoor air quality reports | F25: Closed | G25: Development | K25: Seller: N/A
D26: =+MAX($D$5:D25)+1 -> 17 | E26: Water intrusion/moisture issues | F26: Closed | G26: Development | K26: Seller: N/A
D27: =+MAX($D$5:D26)+1 -> 18 | E27: Deleted | F27: Deleted | G27: Deleted
D28: =+MAX($D$5:D27)+1 -> 19 | E28: Deleted | F28: Deleted | G28: Deleted
E29: Request Drawings + confirm building Specs
D30: =+MAX($D$5:D29)+1 -> 20 | E30: Site Plans/Building Plans / Construction Plans / As-Builts | F30: Closed | G30: Development | K30: Seller: N/A
D31: =+MAX($D$5:D30)+1 -> 21 | E31: Building Permits | F31: Closed | G31: Development | K31: Seller: N/A
D32: =+MAX($D$5:D31)+1 -> 22 | E32: Certificates of Occupancy | F32: Received | G32: Development | K32: Received all but one. 63 Lambert does not exist. See Zoning Cert from Title Company's attorney. CC to decide whether to clean up post-closing
D33: =+MAX($D$5:D32)+1 -> 23 | E33: Building areas - Building GSF, Unit RSF's | F33: Closed | G33: Development | K33: Seller: N/A
D34: =+MAX($D$5:D33)+1 -> 24 | E34: Deleted | F34: Deleted | G34: Deleted
D35: =+MAX($D$5:D34)+1 -> 25 | E35: REAC reports and scores from prior 3 years | F35: Closed | G35: Development | K35: Rec'd 2025, Seller: Only one score from past 5 years
D36: =+MAX($D$5:D35)+1 -> 26 | E36: Capital Needs Assessment | F36: Closed | G36: Development | K36: 2021, Seller: CNA good for 10 years
D37: =+MAX($D$5:D36)+1 -> 27 | E37: Keith Construction budget | F37: Open
D38: PROPERTY MANAGEMENT
E39: Schedule calls with UHM to review (DD materials, budget). Walk property with onsite team
D40: =+MAX($D$5:D39)+1 -> 28 | E40: 2026 Operating Budget | F40: Received | G40: Prop Mgmt
D41: =+MAX($D$5:D40)+1 -> 29 | E41: Management & Occupancy Review past 3 years | F41: Open | K41: Received 2023 and 2025; No 2024 report exists
...

Sheet HAP Assignment Checklist
A2: HAP Assignment Checklist (with HUD Exhibit 2 items)
A3: General Information
A4: Name: | D4: How does 2530 HUD Clearance layer into this? | F4: Seller:
A5: Address: | D5: Any docs we need to get Darryl now? | F5: FHA:
A6: Contract: | F6: PBCA:
A7: New Owner: | F7: HUD AE:
A8: Section 1 | C8: Proposed Owner Information | D8: Responsible Party | E8: CC/MG Notes | F8: Status | G8: Comments
B9: a. | C9: Name and signature block for Proposed Owner entity | D9: John Daniels | G9: Borrower Name:
B10: b. | C10: Organizational Chart for Proposed Owner entity (with percentage interests and roles for all entities and individuals) | D10: Caste - Nixon
B11: c. | C11: Resume for Proposed Owner or sponsor (include any affordable experience) | D11: John Daniels | E11: Will this be both CC and MG?
B12: d. | C12: Articles of Organization/Certificate of Formation/Certificate of Limited Partnership | D12: John Daniels | G12: State of Formation:
B13: e. | C13: Operating Agreement/Limited Partnership Agreement | D13: John Daniels | G13: Date of Operating Agreement:
B14: f. | C14: 2530 Previous Participation submission confirmation in APPS | D14: John Daniels | G14: APPS Submission Number: Confirm entities are registered in Business Partner Registration if paper 2530 is submitted in lieu of APPS submission.
B15: g. | C15: Real Estate Owned (REO) Schedule | D15: John Daniels | E15: Will this be both CC and MG? Trace control
B16: h. | C16: Purchaser's Financial Statement (HUD Form 92417) | D16: John Daniels | E16: Will this be both CC and MG? Trace control
B17: i. | C17: Unique Entity ID Registration Confirmation | D17: John Daniels | E17: Will this be both CC and MG? Trace control | G17: Unique Entity ID:
B18: j. | C18: EIN Number for Proposed Owner entity | D18: John Daniels | E18: Will this be both CC and MG? Trace control | G18: EIN Number:
B19: k. | C19: Confirmation of Fiscal Year End Date | D19: John Daniels | E19: Will this be both CC and MG? Trace control
B20: l. | C20: Certificate of Good Standing | D20: John Daniels | E20: Will this be both CC and MG? Trace control
B21: m. | C21: Authorizing Resolution | D21: John Daniels | E21: Will this be both CC and MG? Trace control
B22: n. | C22: Credit Report for sponsor | D22: John Daniels | E22: Will this be both CC and MG? Trace control
A24: Section 2 | C24: Management Company Information
B25: a. | C25: Resume of Management Company | D25: Caste | E25: From UHM | G25: Name of Management Agent:
B26: b. | C26: Management Agent Certification (HUD Form 9839-B) | D26: N/A | E26: N/A with UHM staying in place?
C27: If new management is being retained at closing:
B28: c. | C28: Management Entity Profile (HUD Form 9832) | D28: Caste | E28: From UHM
B29: d. | C29: 2530 Previous Participation submission confirmation on APPS | D29: Caste | E29: From UHM | G29: APPS Submission Number: Confirm entities are registered in Business Partner Registration if paper 2530 is submitted in lieu of APPS submission.
B30: e. | C30: Proposed Tenant Selection Plan | D30: Caste | E30: From UHM
B31: f. | C31: Proposed Tenant Lease | D31: Caste | E31: From UHM | G31: Need confirmation that the agent will use the HUD form model lease (form HUD-90105a)
B32: g. | C32: Management Agreement with HUD required provisions | D32: Caste | E32: Can we use current or needs to be assigned?
A34: Section 3 | C34: Project Finances and Affordability
B35: a. | C35: Description of financing (LIHTC? Conventional? FHA? Tax-exempt bonds?) | D35: Caste | E35: Will likely be TBD prior to submission. Ok to follow
B36: b. | C36: Pro Forma Net Operating Income | D36: Caste
B37: c. | C37: Pro Forma Sources and Uses | D37: Caste
B38: d. | C38: Estimated closing date | D38: Caste | G38: Closing Date:
B39: e. | C39: Purchase and Sale Agreement and any amendments or assignments | D39: Caste | G39: Executed Date:
B40: f. | C40: Name and address of Lender | D40: Caste | G40: Lender Name:
B41: g. | C41: Name and address of Title Company/Escrow Agent | D41: Caste | G41: Title Name:
B42: h. | C42: Proposed Deed | D42: Caste
B43: i. | C43: Balance Sheet | D43: Caste
...

Sheet Lender Checklist
E3: Northmarq - Lender Checklist
E5: PRIORITY CREDIT ITEMS FOR RATE LOCK | M5: Walker
E6: TBD BORROWING ENTITY | Y6: SENT
E7: 1 | F7: Organizational Chart | G7: Closed | H7: AS | K7: Draft from 1.7.26 | M7: January T-12 Operating Statement (Dec. will suffice)
E8: =+MAX($E7:E$7)+1 -> 2 | F8: Organizational Documents (exec. When available) | G8: Open | H8: AS | K8: RAP UP Partners, LLC OA | M8: Current Rent Roll
E9: =+MAX($E$7:E8)+1 -> 3 | F9: Credit Authorization / Loan History Statement | G9: Open | H9: AS | M9: Schedule of recent Cap Ex repairs (within last two years)
E10: =+MAX($E$7:E9)+1 -> 4 | F10: Current Balance Sheet | G10: Open | H10: AS | M10: Name of proposed management company, summary of their experience, highlighing scattered site and Section 8
M11: Resume/bios for key principals
E12: TBD KEY PRINCIPAL / GUARANTOR | M12: Schedule of REO - unit, occupancy, maturity dates, current lender, noi, market value, DSCR, LTV
E13: =+MAX($E$7:E10)+1 -> 5 | F13: Driver's License or Passport | G13: Open | H13: AS | M13: Financial statements for Caste
E14: =+MAX($E$7:E13)+1 -> 6 | F14: Biography detailing REO & Mgmt Experience | G14: Open | H14: AS
E15: =+MAX($E$7:E14)+1 -> 7 | F15: Credit Authorization / Loan History Statement | G15: Open | H15: AS
E16: =+MAX($E$7:E15)+1 -> 8 | F16: Personal Financial Statements | G16: Open | H16: AS
E17: =+MAX($E$7:E16)+1 -> 9 | F17: RE Schedule and Explanations for all contignecy liabilities | G17: Open | H17: AS
E18: =+MAX($E$7:E17)+1 -> 10 | F18: Verification of Deposits (bank or brokers statements dated within 3 months will suffice) | G18: Open | H18: AS
E20: TBD PRINCIAL INDIVIDUALS
E21: =+MAX($E$7:E18)+1 -> 11 | F21: Driver's License or Passport | G21: Open | H21: AS
E22: =+MAX($E$7:E21)+1 -> 12 | F22: Biography detailing REO & Mgmt Experience | G22: Open | H22: AS
E23: =+MAX($E$7:E22)+1 -> 13 | F23: Credit Authorization / Loan History Statement | G23: Open | H23: AS
E24: =+MAX($E$7:E23)+1 -> 14 | F24: Personal Financial Statements | G24: Open | H24: AS | K24: From Who?
E26: TBD PRINCIPAL ENTITIES
E27: =+MAX($E$7:E24)+1 -> 15 | F27: Organization Documents (exec. When available) | G27: Open | H27: AS
E28: =+MAX($E$7:E27)+1 -> 16 | F28: Credit Authorization / Loan History Statement | G28: Open | H28: AS
E29: =+MAX($E$7:E28)+1 -> 17 | F29: Current Balance Sheet | G29: Open | H29: AS
E31: PROPERTY-LEVEL ITEMS FOR RATE LOCK
E32: OPERATING STATEMENTS
E33: =+MAX($E$7:E32)+1 -> 18 | F33: Historical P&Ls (3 yrs as avail.) | G33: Closed | H33: AS | K33: Uploaded, 2025 thru 11/25
E34: =+MAX($E$7:E33)+1 -> 19 | F34: Current Monthly T-12 | G34: Closed | H34: AS | K34: Included in 18, T-12 from 11/25
E35: =+MAX($E$7:E34)+1 -> 20 | F35: Borrower's Current Budget | G35: Open | H35: AS
E36: =+MAX($E$7:E35)+1 -> 21 | F36: Current Rent Roll(s) (detailed) | G36: Closed | H36: AS | K36: As of 12.31.25
E37: =+MAX($E$7:E36)+1 -> 22 | F37: Collections - 3 months of operating account bank statements for account name to Borrower/Owner | G37: Open | H37: AS
E38: =+MAX($E$7:E37)+1 -> 23 | F38: Collections - Delinquency/Aged Receiveables & Prepaid Report | G38: Closed | H38: AS | K38: As of 12.31.25
E39: =+MAX($E$7:E38)+1 -> 24 | F39: CapEx - Sponsor's recently completed improvements & Lender's receipt of a detailed Cap Ex budget | G39: Open | H39: AS
E40: =+MAX($E$7:E39)+1 -> 25 | F40: Borrower expense comparables for similar properties owned in similar markets (current or prior year P&L data will suffice) | G40: Open | H40: AS
E41: =+MAX($E$7:E40)+1 -> 26 | F41: Property payroll summary | G41: Open | H41: AS
E42: =+MAX($E$7:E41)+1 -> 27 | F42: Cert. of Occ. - if readily available | G42: Closed | H42: AS | K42: 63 Lambert not included
E44: INSURANCE, LEGAL, & THIRD-PARTY ITEMS REQUIRED FOR RATE LOCK
E45: INSURANCE, LEGAL, & THIRD-PARTY ITEMS
E46: =+MAX($E$7:E45)+1 -> 28 | F46: Lender's acceptable insurance review of property and liability insurance policies (inc. Accord 25, 27) and annual premium quote | G46: Open | H46: AS | K46: Getting quote from McGriff, current: Traveler's
E47: =+MAX($E$7:E46)+1 -> 29 | F47: Lender inspection with acceptable findings (acceptable review of corporate units, leases, tenant ledgers, etc.) | G47: Open | H47: AS | I47: Northmarq
...

Sheet Deal Team
B2: Role | C2: Organization | D2: Name
B3: Acquiror | C3: Caste Capital | D3: Bode Adunbarin
B4: Acquiror | C4: Caste Capital | D4: David Stewart
B5: Acquiror | C5: Caste Capital | D5: Patrick Kimble
B6: Acquiror | C6: Caste Capital | D6: Alex Schultz
B7: Acquiror | C7: Menkiti Group | D7: Bo Menkiti
B8: Acquiror | C8: Menkiti Group | D8: John Daniels
B9: Acquiror/Seller | C9: Catalyst Ventures | D9: Darryl Settles
B10: Broker | C10: Colliers | D10: Jeanne Pinnado
B11: Legal Counsel | C11: Nixon Peabody | D11: Alex Rosso
B12: HAP Contract Administrator | C12: MassHousing | D12: TBC
B13: 3P - Physical Needs Assessor | C13: TBC | D13: TBC
... B24: Debt Financing (Option) | C24: LISC | D24: Gustavo Quiroga

Sheet Cost Schedule
B2: DD SCHEDULE / COST TRACKER
C4: Phase | D4: Task | E4: Party | F4: Start | G4: Duration | H4: End | I4: Budget | J4: Proposal Cost | K4: Spent | L4: Remaining | O4: 46013 | P4: =+EOMONTH(O4,1) -> 46053 | Q4: =+EOMONTH(P4,1) -> 46081 | R4: =+EOMONTH(Q4,1) -> 46112 | S4: =+EOMONTH(R4,1) -> 46142 | T4: =+EOMONTH(S4,1) -> 46173 | U4: =+EOMONTH(T4,1) -> 46203 | V4: =+EOMONTH(U4,1) -> 46234 | W4: =+EOMONTH(V4,1) -> 46265 | X4: =+EOMONTH(W4,1) -> 46295 | Z4: CHECK
C5: Acquisition - Legal | D5: Execute LOI | E5: Acquiror/Seller | F5: 46013 | G5: 0 | H5: =+F5+G5 -> 46013 | I5: 0.0001 | J5: 0.0001 | K5: 0.0001 | L5: =+J5-K5 -> 0 | O5: =+IF(AND(O$4>=$F5,O$4<=$H5),$J5,0) -> 0.0001 | P5: =+IF(AND(P$4>=$F5,P$4<=$H5),$J5,0) -> 0 | Q5: =+IF(AND(Q$4>=$F5,Q$4<=$H5),$J5,0) -> 0 | R5: =+IF(AND(R$4>=$F5,R$4<=$H5),$J5,0) -> 0 | S5: =+IF(AND(S$4>=$F5,S$4<=$H5),$J5,0) -> 0 | T5: =+IF(AND(T$4>=$F5,T$4<=$H5),$J5,0) -> 0 | U5: =+IF(AND(U$4>=$F5,U$4<=$H5),$J5,0) -> 0 | V5: =+IF(AND(V$4>=$F5,V$4<=$H5),$J5,0) -> 0 | ... X5: =+IF(AND(X$4>=$F5,X$4<=$H5),$J5,0) -> 0 | Z5: =+SUM(O5:X5)-J5 -> 0
C6: Acquisition - Legal | D6: Draft and execute PSA | E6: Acquiror | F6: =+$H$5 -> 46013 | G6: 40 | H6: =+F6+G6 -> 46053 | I6: 7500 | J6: 7500 | K6: 0 | L6: =+J6-K6 -> 7500 | O6: 0 | P6: 0 | Q6: 0 | R6: 0 | S6: 0 | T6: =+$J6 -> 7500 | U6: 0 | V6: 0 | W6: 0 | X6: 0 | Z6: =+SUM(O6:X6)-J6 -> 0
C7: Acquisition - Legal | D7: Draft and execute LPA, JVAs | E7: Acquiror/Seller/Nixon | F7: =+$H$5 -> 46013 | G7: 40 | H7: =+F7+G7 -> 46053 | I7: 10000 | J7: 10000 | K7: 0 | L7: =+J7-K7 -> 10000 | O7: 0 | P7: 0 | Q7: 0 | R7: 0 | S7: 0 | T7: =+$J7 -> 10000 | U7: 0 | V7: 0 | W7: 0 | X7: 0 | Z7: =+SUM(O7:X7)-J7 -> 0
C8: Acquisition - Legal | D8: Draft and execute Caste GP formation doc | E8: CC, Nixon | F8: =+$H$5 -> 46013 | G8: 40 | H8: =+F8+G8 -> 46053 | I8: 2500 | J8: 2500 | K8: 0 | L8: =+J8-K8 -> 2500 | O8: 0 | P8: 0 | Q8: 0 | R8: 0 | S8: 0 | T8: =+$J8 -> 2500 | U8: 0 | V8: 0 | W8: 0 | X8: 0 | Z8: =+SUM(O8:X8)-J8 -> 0
C9: DD / HUD Approvals | D9: Mgmt agent and ownership approvals, HAP Contract Review & Assumption | E9: Acquiror, Seller, Nixon Peabody, MassHousing | F9: =+$H$6 -> 46053 | G9: =60+60 -> 120 | H9: =+F9+G9 -> 46173 | I9: 35000 | J9: 35000 | K9: 0 | L9: =+J9-K9 -> 35000 | O9: =+IF(AND(O$4>=$F9,O$4<=$H9),$J9,0) -> 0 | P9: 0 | Q9: 0 | R9: 0 | S9: 0 | T9: =+$J9 -> 35000 | U9: 0 | V9: 0 | W9: 0 | X9: 0 | Z9: =+SUM(O9:X9)-J9 -> 0
C10: Acquisition - Legal | D10: Draft and execute PMAs | E10: Acquiror/Seller/Nixon | F10: =+$H$5 -> 46013 | G10: 40 | H10: =+F10+G10 -> 46053 | I10: 12500 | J10: 12500 | K10: 0 | L10: =+J10-K10 -> 12500 | O10: 0 | P10: 0 | Q10: 0 | R10: 0 | S10: 0 | T10: =+$J10 -> 12500 | U10: 0 | V10: 0 | W10: 0 | X10: 0 | Z10: =+SUM(O10:X10)-J10 -> 0
C11: Due Diligence | D11: Zoning Certificate / Letter | E11: Acquiror, 3Ps | F11: =+$H$6+1 -> 46054 | G11: 60 | H11: =+F11+G11 -> 46114 | I11: 5000 | J11: 0 | K11: 0 | L11: =+J11-K11 -> 0 | O11: 0 | P11: 0 | Q11: 0 | R11: 0 | S11: 0 | T11: =+$J11 -> 0 | U11: 0 | V11: 0 | W11: 0 | X11: 0 | Z11: =+SUM(O11:X11)-J11 -> 0
C12: Due Diligence | D12: Title Review | E12: Acquiror, 3Ps | F12: =+$H$6+1 -> 46054 | G12: 60 | H12: =+F12+G12 -> 46114 | I12: 5000 | J12: 5000 | K12: 0 | L12: =+J12-K12 -> 5000 | O12: 0 | P12: 0 | Q12: 0 | R12: 0 | S12: 0 | T12: =+$J12 -> 5000 | U12: 0 | V12: 0 | W12: 0 | X12: 0 | Z12: =+SUM(O12:X12)-J12 -> 0
C13: Due Diligence | D13: Order ALTA Survey | E13: Acquiror, 3Ps | F13: =+$H$6+1 -> 46054 | G13: 60 | H13: =+F13+G13 -> 46114 | I13: 45000 | J13: 40000 | K13: 0 | L13: =+J13-K13 -> 40000 | O13: 0 | P13: 0 | Q13: 0 | R13: 0 | S13: 0 | T13: =+$J13 -> 40000 | U13: 0 | V13: 0 | W13: 0 | X13: 0 | Z13: =+SUM(O13:X13)-J13 -> 0
C14: Due Diligence | D14: Order PCA/CNA | E14: Acquiror, 3Ps | F14: =+$H$6+1 -> 46054 | G14: 60 | H14: =+F14+G14 -> 46114 | I14: =60000 -> 60000 | J14: 8050 | K14: 0 | L14: =+J14-K14 -> 8050 | O14: 0 | P14: 0 | Q14: 0 | R14: =+$J14*0.75 -> 6037.5 | S14: =+$J14*0.25 -> 2012.5 | T14: 0 | U14: 0 | V14: 0 | W14: 0 | X14: 0 | Z14: =+SUM(O14:X14)-J14 -> 0
C15: Due Diligence | D15: Phase I ESA | E15: Acquiror, 3Ps | F15: =+$H$6+1 -> 46054 | G15: 60 | H15: =+F15+G15 -> 46114 | I15: =60000 -> 60000 | J15: 13200 | K15: 0 | L15: =+J15-K15 -> 13200 | O15: 0 | P15: 0 | Q15: 0 | R15: =+$J15*0.75 -> 9900 | S15: =+$J15*0.25 -> 3300 | T15: 0 | U15: 0 | V15: 0 | W15: 0 | X15: 0 | Z15: =+SUM(O15:X15)-J15 -> 0
C16: Due Diligence | D16: Misc | E16: Acquiror, 3Ps | F16: =+$H$6+1 -> 46054 | G16: 60 | H16: =+F16+G16 -> 46114 | I16: 5000 | J16: 0 | K16: 0 | L16: =+J16-K16 -> 0 | O16: 0 | P16: 0 | Q16: 0 | R16: 0 | S16: 0 | T16: =+$J16 -> 0 | U16: 0 | V16: 0 | W16: 0 | X16: 0 | Z16: =+SUM(O16:X16)-J16 -> 0
C17: Due Diligence | D17: Rent Comp Study | E17: Acquiror, APR | F17: =+$H$6 -> 46053 | G17: 45 | H17: =+F17+G17 -> 46098 | I17: 0 | J17: 7000 | K17: 0 | L17: =+J17-K17 -> 7000 | O17: 0 | P17: 0 | Q17: =+$J17 -> 7000 | R17: 0 | S17: 0 | T17: 0 | U17: 0 | V17: 0 | W17: 0 | X17: 0 | Z17: =+SUM(O17:X17)-J17 -> 0
C18: Due Diligence | D18: 2530 Clearance Work | E18: Acquiror, APR | F18: =+$H$6 -> 46053 | G18: 45 | H18: =+F18+G18 -> 46098 | I18: 0 | J18: 7500 | K18: 0 | L18: =+J18-K18 -> 7500 | O18: 0 | P18: 0 | Q18: 0 | R18: =+$J18*0.5 -> 3750 | S18: =+$J18*0.5 -> 3750 | T18: 0 | U18: 0 | V18: 0 | W18: 0 | X18: 0 | Z18: =+SUM(O18:X18)-J18 -> 0
C19: Due Diligence | D19: Ryan Tax Report | E19: Acquiror, 3Ps | F19: =+$H$6+1 -> 46054 | G19: 60 | H19: =+F19+G19 -> 46114 | I19: 0 | J19: 2000 | K19: 0 | L19: =+J19-K19 -> 2000 | O19: 0 | P19: 0 | Q19: 0 | R19: =+$J19 -> 2000 | S19: 0 | T19: 0 | U19: 0 | V19: 0 | W19: 0 | X19: 0 | Z19: =+SUM(O19:X19)-J19 -> 0
C20: Financing | D20: Lender legal fees | E20: Acquiror, Lender, Nixon | F20: =+$H$6+1 -> 46054 | G20: 60 | H20: =+F20+G20 -> 46114 | I20: 27000 | J20: 15000 | K20: 0 | L20: =+J20-K20 -> 15000 | O20: 0 | P20: 0 | Q20: 0 | R20: =+$J20 -> 15000 | S20: 0 | T20: 0 | U20: 0 | V20: 0 | W20: 0 | X20: 0 | Z20: =+SUM(O20:X20)-J20 -> 0
C21: Financing | D21: Lender Reports & fees | E21: Acquiror, Lender, Nixon | F21: =+$H$6+1 -> 46054 | G21: 60 | H21: =+F21+G21 -> 46114 | I21: 20000 | J21: =15000+13000 -> 28000 | K21: 0 | L21: =+J21-K21 -> 28000 | O21: 0 | P21: 0 | Q21: 0 | R21: =+$J21 -> 28000 | S21: 0 | T21: 0 | U21: 0 | V21: 0 | W21: 0 | X21: 0 | Z21: =+SUM(O21:X21)-J21 -> 0
C22: Due Diligence | D22: Affordable consultant | E22: Acquiror, Jacques | F22: =+F9 -> 46053 | G22: =+G9 -> 120 | H22: =+F22+G22 -> 46173 | I22: =50500 -> 50500 | J22: =+I22 -> 50500 | K22: 0 | L22: =+J22-K22 -> 50500 | O22: 0 | P22: 0 | Q22: 0 | R22: 0 | S22: 0 | T22: =+$J22 -> 50500 | U22: 0 | V22: 0 | W22: 0 | X22: 0 | Z22: =+SUM(O22:X22)-J22 -> 0
C23: Contingency | F23: =+$H$5 -> 46013 | G23: 40 | H23: =+F23+G23 -> 46053 | I23: 0 | J23: =10%*SUM(J5:J22,-J22) -> 19325 | K23: 0 | L23: =+J23-K23 -> 19325 | O23: 0 | P23: 0 | Q23: 0 | R23: 0 | S23: 0 | T23: =+$J23 -> 19325 | U23: 0 | V23: 0 | W23: 0 | X23: 0 | Z23: =+SUM(O23:X23)-J23 -> 0
C24: Deposit #1 | D24: Escrow deposit ($50K at PSA signing) | E24: Acquiror | F24: =+$H$6 -> 46053 | G24: 5 | H24: =+F24+G24 -> 46058 | I24: 50000 | J24: =+I24 -> 50000 | K24: 0 | L24: =+J24-K24 -> 50000 | O24: 0 | P24: 0 | Q24: =+$J24 -> 50000 | R24: 0 | S24: 0 | T24: 0 | U24: 0 | V24: 0 | W24: 0 | X24: 0 | Z24: =+SUM(O24:X24)-J24 -> 0
C25: Deposit #2 | D25: Escrow deposit ($150K at DD) | E25: Acquiror | F25: =+$H$6+60 -> 46113 | G25: 5 | H25: =+F25+G25 -> 46118 | I25: 150000 | J25: =+I25 -> 150000 | K25: 0 | L25: =+J25-K25 -> 150000 | O25: 0 | P25: 0 | Q25: 0 | R25: 0 | S25: =+$J25 -> 150000 | T25: 0 | U25: 0 | V25: 0 | W25: 0 | X25: 0 | Z25: =+SUM(O25:X25)-J25 -> 0
C26: Total (Incl. Deposits) | I26: =SUM(I5:I25) -> 545000 | J26: =SUM(J5:J25) -> 463075 | K26: =SUM(K5:K25) -> 0.0001 | O26: =SUM(O5:O25) -> 0.0001 | P26: =SUM(P5:P25) -> 0 | Q26: =SUM(Q5:Q25) -> 57000 | R26: =SUM(R5:R25) -> 64687.5 | S26: =SUM(S5:S25) -> 159062.5 | T26: =SUM(T5:T25) -> 182325 | U26: =SUM(U5:U25) -> 0 | V26: =SUM(V5:V25) -> 0 | ... X26: =SUM(X5:X25) -> 0 | Z26: =+SUM(O26:X26)-J26 -> 0
C27: Total (Excl. Deposits) | I27: =+I26-SUM(I25,I24) -> 345000 | J27: =+J26-SUM(J25,J24) -> 263075 | K27: =+K26-SUM(K25,K24) -> 0.0001 | O27: =+O26-SUM(O25,O24) -> 0.0001 | P27: =+P26-SUM(P25,P24) -> 0 | Q27: =+Q26-SUM(Q25,Q24) -> 7000 | R27: =+R26-SUM(R25,R24) -> 64687.5 | S27: =+S26-SUM(S25,S24) -> 9062.5 | T27: =+T26-SUM(T25,T24) -> 182325 | U27: =+U26-SUM(U25,U24) -> 0 | V27: =+V26-SUM(V25,V24) -> 0 | ... X27: =+X26-SUM(X25,X24) -> 0 | Z27: =+SUM(O27:X27)-J27 -> 0
C29: Note: | P29: =+P26*50% -> 0 | Q29: =+Q26*50% -> 28500 | R29: =+R26*50% -> 32343.75 | S29: =+S26*50% -> 79531.25 | T29: =+T26*50% -> 91162.5
C30: Dates are approximations. | P30: =+P27*50% -> 0 | Q30: =+Q27*50% -> 3500 | R30: =+R27*50% -> 32343.75 | S30: =+S27*50% -> 4531.25 | T30: =+T27*50% -> 91162.5
P31: =+P30/4 -> 0 | Q31: =+Q30/4 -> 875 | R31: =+R30/4 -> 8085.9375 | S31: =+S30/4 -> 1132.8125 | T31: =+T30/4 -> 22790.625

Sheet External - DD List
D2: DUE DILIGENCE REQUEST LIST | F2: 45992
D3: RAP UP Portfolio
I4: =+TODAY() -> 46217
C5: DIV Folder | D5: Item # | E5: Document | F5: Status | G5: Department | H5: Responsible Party | I5: DIV Comment | J5: Partner Comment
D6: LEASING & MARKETING
D7: =+MAX($D$5:D5)+1 -> 1 | E7: Residential Leases & House Rules | F7: Open | G7: Leasing / Marketing
D8: =+MAX($D$5:D7)+1 -> 2 | E8: License Agreements (if applicable) | F8: Open | G8: Leasing / Marketing
D9: =+MAX($D$5:D8)+1 -> 3 | E9: Indemnities (if applicable) | F9: Open | G9: Leasing / Marketing
D10: PHYSICAL / PROPERTY
E11: Title and Zoning | F11: Open | G11: Development
D12: =+MAX($D$5:D11)+1 -> 4 | E12: ALTA Survey | F12: Open | G12: Development
D13: =+MAX($D$5:D12)+1 -> 5 | E13: Existing Title Insurance Policy | F13: Open | G13: Development
D14: =+MAX($D$5:D13)+1 -> 6 | E14: Deleted | F14: Deleted | G14: Deleted
D15: =+MAX($D$5:D14)+1 -> 7 | E15: All City/State permits | F15: Open | G15: Development
D16: =+MAX($D$5:D15)+1 -> 8 | E16: Easement Documents (if applicable) | F16: Open | G16: Development
D17: =+MAX($D$5:D16)+1 -> 9 | E17: Confirm FEMA Flood Vulnerable Status | F17: Open | G17: Development
D18: =+MAX($D$5:D17)+1 -> 10 | E18: Permits Required for Property Operation (e.g. flammable fuel storage) | F18: Open | G18: Development
E19: Environmental Information
D20: =+MAX($D$5:D19)+1 -> 11 | E20: Phase 1 and 2 ESA | F20: Open | G20: Development
D21: =+MAX($D$5:D20)+1 -> 12 | E21: Hazardous Materials report | F21: Open | G21: Development
D22: =+MAX($D$5:D21)+1 -> 13 | E22: Geotechnical soils report | F22: Open | G22: Development
D23: =+MAX($D$5:D22)+1 -> 14 | E23: Lead abatement/compliance report | F23: Open | G23: Development
D24: =+MAX($D$5:D23)+1 -> 15 | E24: Mold reports/remediation | F24: Open | G24: Development
D25: =+MAX($D$5:D24)+1 -> 16 | E25: Indoor air quality reports | F25: Open | G25: Development
D26: =+MAX($D$5:D25)+1 -> 17 | E26: Water intrusion/moisture issues | F26: Open | G26: Development
D27: =+MAX($D$5:D26)+1 -> 18 | E27: Deleted | F27: Deleted | G27: Deleted
D28: =+MAX($D$5:D27)+1 -> 19 | E28: Deleted | F28: Deleted | G28: Deleted
E29: Drawings
D30: =+MAX($D$5:D29)+1 -> 20 | E30: Site Plans/Building Plans / Construction Plans / As-Builts | F30: Open | G30: Development
D31: =+MAX($D$5:D30)+1 -> 21 | E31: Building Permits | F31: Open | G31: Development
D32: =+MAX($D$5:D31)+1 -> 22 | E32: Certificates of Occupancy | F32: Open | G32: Development
D33: =+MAX($D$5:D32)+1 -> 23 | E33: Building areas - Building GSF, Unit RSF's | F33: Open | G33: Development
D34: =+MAX($D$5:D33)+1 -> 24 | E34: Deleted | F34: Deleted | G34: Deleted
D35: =+MAX($D$5:D34)+1 -> 25 | E35: REAC reports and scores from prior 3 years | F35: Open | G35: Development
D36: =+MAX($D$5:D35)+1 -> 26 | E36: Capital Needs Assessment | F36: Open | G36: Development
D37: PROPERTY MANAGEMENT
D38: =+MAX($D$5:D36)+1 -> 27 | E38: 2026 Operating Budget | F38: Open | G38: Prop Mgmt
D39: =+MAX($D$5:D38)+1 -> 28 | E39: Management & Occupancy Review past 3 years
D40: =+MAX($D$5:D39)+1 -> 29 | E40: Personal Property Inventory | F40: Open | G40: Prop Mgmt
D41: =+MAX($D$5:D40)+1 -> 30 | E41: Photographs | F41: Open | G41: Prop Mgmt
...
